Workbook

Sheet Products for specification 2
C2: СПЕЦИФИКАЦИЯ №02 | K2: !!! | L2: !!!
A3: TAG # | B3: SKU / Артикул | C3: Line Item Description / Наименование позиции | D3: ед. изм | E3: кол-во продукта в единице | F3: Кол-во тары | G3: Общее кол-во продукта | H3: цена за единицу, руб без НДС | I3: Стоимость, руб без НДС | K3: цена за единицу, руб без НДС, NEW, с дисконтом!!!! | L3: Стоимость, руб без НДС, с дисконтом!!! NEW | M3: цена за единицу, руб без НДС, NEW | N3: Стоимость, руб без НДС, NEW | O3: дельта | P3: Общее кол-во продукта, NEW | Q3: Кол-во тары, NEW | R3: Л/КГ В БОЧКЕ | S3: SKU / Артикул | T3: Предлагаемый к поставке в 2026 году продукт
A4: 0.26 | B4: 10011103 | C4: LEMARC COOLGUARD G12+ Extra / LEMARC COOLGUARD G12+ Extra | D4: л | E4: 208 | F4: 483 | G4: 100464 | H4: 176.75 | I4: =G4*H4 -> 17757012 | K4: =M4 -> 176.75 | L4: =K4*P4 -> 17757012 | M4: =I4/P4 -> 176.75 | N4: =M4*P4 -> 17757012 | O4: =P4-G4 -> 0 | P4: =Q4*R4 -> 100464 | Q4: 483 | R4: 208 | S4: 10081103 | T4: LEMARC FROSTGUARD G12+ Extra / LEMARC FROSTGUARD G12+ Extra | U4: переименование продукта
A5: 0.27 | B5: 13621101 | C5: LEMARC AEROGUARD SH 46 / LEMARC AEROGUARD SH 46 | D5: л | E5: 208 | F5: 97 | G5: 20176 | H5: 200.36 | I5: =G5*H5 -> 4042463.4 | K5: =M5 -> 200.36 | L5: =K5*P5 -> 4042463.4 | M5: =I5/P5 -> 200.36 | N5: =M5*P5 -> 4042463.4 | O5: =P5-G5 -> 0 | P5: =Q5*R5 -> 20176 | Q5: 97 | R5: 208 | S5: 13621101 | T5: LEMARC AEROGUARD SH 46 / LEMARC AEROGUARD SH 46
A6: 0.28 | B6: 14021101 | C6: LEMARC PNEUMOGUARD 100 / LEMARC PNEUMOGUARD 100 | D6: л | E6: 208 | F6: 8 | G6: 1664 | H6: 176.75 | I6: =G6*H6 -> 294112 | K6: =M6 -> 176.75 | L6: =K6*P6 -> 294112 | M6: =I6/P6 -> 176.75 | N6: =M6*P6 -> 294112 | O6: =P6-G6 -> 0 | P6: =Q6*R6 -> 1664 | Q6: 8 | R6: 208 | S6: 14021101 | T6: LEMARC PNEUMOGUARD 100 / LEMARC PNEUMOGUARD 100
A7: 0.29 | B7: 14111101 | C7: LEMARC PNEUMOGUARD 32 / LEMARC PNEUMOGUARD 32 | D7: л | E7: 208 | F7: 20 | G7: 4160 | H7: 159.23 | I7: =G7*H7 -> 662396.8 | K7: =M7 -> 159.23 | L7: =K7*P7 -> 662396.8 | M7: =I7/P7 -> 159.23 | N7: =M7*P7 -> 662396.8 | O7: =P7-G7 -> 0 | P7: =Q7*R7 -> 4160 | Q7: 20 | R7: 208 | S7: 14111101 | T7: LEMARC PNEUMOGUARD 32 / LEMARC PNEUMOGUARD 32 OIL
A8: 0.30 | B8: 12001101 | C8: LEMARC GEAPARD DVI LV / LEMARC GEAPARD DVI LV | D8: л | E8: 208 | F8: 31 | G8: 6448 | H8: 328.85 | I8: =G8*H8 -> 2120424.8 | K8: =M8 -> 328.85 | L8: =K8*P8 -> 2120424.8 | M8: =I8/P8 -> 328.85 | N8: =M8*P8 -> 2120424.8 | O8: =P8-G8 -> 0 | P8: =Q8*R8 -> 6448 | Q8: 31 | R8: 208 | S8: 12001101 | T8: LEMARC GEAPARD DVI LV / LEMARC GEAPARD DVI LV
A9: 0.31 | B9: 11951101 | C9: LEMARC GEAPARD X4/X5 75W90 / LEMARC GEAPARD X4/X5 75W90 | D9: л | E9: 208 | F9: 707 | G9: 147056 | H9: 600.42 | I9: =G9*H9 -> 88295364 | K9: =M9 -> 599.99975 | L9: =K9*P9 -> 88295364 | M9: =I9/P9 -> 599.99975 | N9: =M9*P9 -> 88295364 | O9: =P9-G9 -> 103 | P9: =Q9*R9 -> 147159 | Q9: 747 | R9: 197 | S9: 1495990 | T9: TEBOIL HYPOID 75W90 | U9: 170 кг
A10: 0.32 | B10: 14121101 | C10: LEMARC GEAPARD X5 75W140 / LEMARC GEAPARD X5 75W140 | D10: л | E10: 208 | F10: 213 | G10: 44304 | H10: 501.38 | I10: =G10*H10 -> 22213140 | K10: =M10 -> 501.38 | L10: =K10*P10 -> 22213140 | M10: =I10/P10 -> 501.38 | N10: =M10*P10 -> 22213140 | O10: =P10-G10 -> 0 | P10: =Q10*R10 -> 44304 | Q10: 213 | R10: 208 | S10: 14121101 | T10: LEMARC GEAPARD X5 75W140 / LEMARC GEAPARD X5 75W140
A11: 0.34 | B11: 14131101 | C11: LEMARC LEGUARD MPV LT / LEMARC LEGUARD MPV LT | D11: л | E11: 208 | F11: 235 | G11: 48880 | H11: 187.83 | I11: =G11*H11 -> 9181130.4 | K11: =M11 -> 187.83 | L11: =K11*P11 -> 9181130.4 | M11: =I11/P11 -> 187.83 | N11: =M11*P11 -> 9181130.4 | O11: =P11-G11 -> 0 | P11: =Q11*R11 -> 48880 | Q11: 235 | R11: 208 | S11: 14131101 | T11: LEMARC LEGUARD MPV LT / LEMARC LEGUARD MPV LT
A12: 0.35 | B12: 14141101 | C12: LEMARC LEGUARD AC 5W30 / LEMARC LEGUARD AC 5W30 | D12: л | E12: 208 | F12: 508 | G12: 105664 | H12: 292.07 | I12: =G12*H12 -> 30861284 | K12: =M12 -> 292.07 | L12: =K12*P12 -> 30861284 | M12: =I12/P12 -> 292.07 | N12: =M12*P12 -> 30861284 | O12: =P12-G12 -> 0 | P12: =Q12*R12 -> 105664 | Q12: 508 | R12: 208 | S12: 14141101 | T12: LEMARC LEGUARD AC 5W30 / LEMARC LEGUARD AC 5W30
A13: 0.36 | B13: 14151101 | C13: LEMARC LEGUARD 40 0W40 / LEMARC LEGUARD 40 0W40 | D13: л | E13: 208 | F13: 3061 | G13: 636688 | H13: 545.19 | I13: =G13*H13 -> 3.4711593e+08 | K13: =M13 -> 545.19 | L13: =K13*P13 -> 3.4711593e+08 | M13: =I13/P13 -> 545.19 | N13: =M13*P13 -> 3.4711593e+08 | O13: =P13-G13 -> 0 | P13: =Q13*R13 -> 636688 | Q13: 3061 | R13: 208 | S13: 14151101 | T13: LEMARC LEGUARD 40 0W40 / LEMARC LEGUARD 40 0W40
A14: 0.37 | B14: 14161101 | C14: LEMARC CARTERRA SH 150/ LEMARC CARTERRA SH 150 | D14: л | E14: 208 | F14: 129 | G14: 26832 | H14: 530.05 | I14: =G14*H14 -> 14222302 | K14: =M14 -> 530.05 | L14: =K14*P14 -> 14222302 | M14: =I14/P14 -> 530.05 | N14: =M14*P14 -> 14222302 | O14: =P14-G14 -> 0 | P14: =Q14*R14 -> 26832 | Q14: 129 | R14: 208 | S14: 14161101 | T14: LEMARC CARTERRA SH 150/ LEMARC CARTERRA SH 150
A15: 0.38 | B15: 14171101 | C15: LEMARC CARTERRA SH 220 / LEMARC CARTERRA SH 220 | D15: л | E15: 208 | F15: 34 | G15: 7072 | H15: 551.25 | I15: =G15*H15 -> 3898440 | K15: =M15 -> 551.25 | L15: =K15*P15 -> 3898440 | M15: =I15/P15 -> 551.25 | N15: =M15*P15 -> 3898440 | O15: =P15-G15 -> 0 | P15: =Q15*R15 -> 7072 | Q15: 34 | R15: 208 | S15: 14171101 | T15: LEMARC CARTERRA SH 220 / LEMARC CARTERRA SH 220
A16: 0.39 | B16: 14181101 | C16: LEMARC CARTERRA SH 680 / LEMARC CARTERRA SH 680 | D16: л | E16: 208 | F16: 68 | G16: 14144 | H16: 686.05 | I16: =G16*H16 -> 9703491.2 | K16: =M16 -> 683.0693 | L16: =K16*P16 -> 9703491.2 | M16: =I16/P16 -> 683.0693 | N16: =M16*P16 -> 9703491.2 | O16: =P16-G16 -> 61.72 | P16: =Q16*R16 -> 14205.72 | Q16: 69 | R16: 205.88 | S16: 3475721 | T16: TEBOIL SYPRES EXTRA 680 | U16: 175 кг
A17: 0.40 | B17: 12311101 | C17: LEMARC HYDRARD XV 32 / LEMARC HYDRARD XV 32 | D17: л | E17: 208 | F17: 9 | G17: 1872 | H17: 267.19 | I17: =G17*H17 -> 500179.68 | K17: =M17 -> 267.19 | L17: =K17*P17 -> 500179.68 | M17: =I17/P17 -> 267.19 | N17: =M17*P17 -> 500179.68 | O17: =P17-G17 -> 0 | P17: =Q17*R17 -> 1872 | Q17: 9 | R17: 208 | S17: 12311101 | T17: LEMARC HYDRARD XV 32 / LEMARC HYDRARD XV 32
A18: 0.41 | B18: 14191101 | C18: LEMARC HYDRARD HVLP-ZF LT 32 / LEMARC HYDRARD HVLP-ZF LT 32 | D18: л | E18: 208 | F18: 1373 | G18: 285584 | H18: 174.7 | I18: =G18*H18 -> 49891525 | K18: =M18 -> 174.7 | L18: =K18*P18 -> 49891525 | M18: =I18/P18 -> 174.7 | N18: =M18*P18 -> 49891525 | O18: =P18-G18 -> 0 | P18: =Q18*R18 -> 285584 | Q18: 1373 | R18: 208 | S18: 14191101 | T18: LEMARC HYDRARD HVLP-ZF LT 32 / LEMARC HYDRARD HVLP-ZF LT 32
A19: 0.42 | B19: 15000018 | C19: LEMARC GREASEGUARD EP 0 / LEMARC GREASEGUARD EP 0 | D19: кг | E19: 180 | F19: 107 | G19: 19260 | H19: 467.09 | I19: =G19*H19 -> 8996153.4 | K19: =M19*0.98 -> 457.7482 | L19: =K19*P19 -> 8816230.3 | M19: =I19/P19 -> 467.09 | N19: =M19*P19 -> 8996153.4 | O19: =P19-G19 -> 0 | P19: =Q19*R19 -> 19260 | Q19: 107 | R19: 180 | S19: 1558960 | T19: ЛУКОЙЛ ПОЛИФЛЕКС ЕР 0-160
A20: 0.43 | B20: 15000019 | C20: LEMARC GREASEGUARD EP 1 / LEMARC GREASEGUARD EP 1 | D20: кг | E20: 180 | F20: 249 | G20: 44820 | H20: 450.6 | I20: =G20*H20 -> 20195892 | K20: =M20*0.98 -> 441.588 | L20: =K20*P20 -> 19791974 | M20: =I20/P20 -> 450.6 | N20: =M20*P20 -> 20195892 | O20: =P20-G20 -> 0 | P20: =Q20*R20 -> 44820 | Q20: 249 | R20: 180 | S20: 1558966 | T20: ЛУКОЙЛ ПОЛИФЛЕКС ЕР 1-160
A21: 0.44 | B21: 10021102 | C21: LEMARC GREASEGUARD OG EP 0 / LEMARC GREASEGUARD OG EP 0 | D21: кг | E21: 180 | F21: 59 | G21: 10620 | H21: 1539 | I21: =G21*H21 -> 16344180 | K21: =M21*0.98 -> 1508.22 | L21: =K21*P21 -> 16017296 | M21: =I21/P21 -> 1539 | N21: =M21*P21 -> 16344180 | O21: =P21-G21 -> 0 | P21: =Q21*R21 -> 10620 | Q21: 59 | R21: 180 | S21: 1682082 | T21: ЛУКОЙЛ КАРБОФЛЕКС OG 0-4000 HD
A22: 0.46 | B22: 15000020 | C22: LEMARC GREASEGUARD MS EP 2 / LEMARC GREASEGUARD MS EP 2 | D22: кг | E22: 180 | F22: 5 | G22: 900 | H22: 1160.27 | I22: =G22*H22 -> 1044243 | K22: =M22*0.98 -> 1137.0646 | L22: =K22*P22 -> 1023358.1 | M22: =I22/P22 -> 1160.27 | N22: =M22*P22 -> 1044243 | O22: =P22-G22 -> 0 | P22: =Q22*R22 -> 900 | Q22: 5 | R22: 180 | S22: 1559874 | T22: ЛУКОЙЛ ПОЛИФЛЕКС ЕР 2-160 HD
A23: 0.48 | B23: 10020902 | C23: LEMARC GREASEGUARD OG EP 0 / LEMARC GREASEGUARD OG EP 0 | D23: кг | E23: 18 | F23: 120 | G23: 2160 | H23: 1729.8 | I23: =G23*H23 -> 3736368 | K23: =K21 -> 1508.22 | L23: =K23*P23 -> 3257755.2 | M23: =I23/P23 -> 1729.8 | N23: =M23*P23 -> 3736368 | O23: =P23-G23 -> 0 | P23: =Q23*R23 -> 2160 | Q23: 12 | R23: 180 | S23: 1682082 | T23: ЛУКОЙЛ КАРБОФЛЕКС OG 0-4000 HD | U23: замена фасовки 18 кг на 180 кг
A24: 0.49 | B24: 10031102 | C24: LEMARC GREASEGUARD OG EP 000 / LEMARC GREASEGUARD OG EP 000 | D24: кг | E24: 180 | F24: 56 | G24: 10080 | H24: 1482 | I24: =G24*H24 -> 14938560 | K24: =M24*0.98 -> 1452.36 | L24: =K24*P24 -> 14639789 | M24: =I24/P24 -> 1482 | N24: =M24*P24 -> 14938560 | O24: =P24-G24 -> 0 | P24: =Q24*R24 -> 10080 | Q24: 56 | R24: 180 | S24: 1683355 | T24: ЛУКОЙЛ КАРБОФЛЕКС OG 000-1500 HD
A25: 0.50 | B25: 15000021 | C25: LEMARC GREASEGUARD OG EP 000 / LEMARC GREASEGUARD OG EP 000 | D25: кг | E25: 18 | F25: 559 | G25: 10062 | H25: 1646.4 | I25: =G25*H25 -> 16566077 | K25: =K24 -> 1452.36 | L25: =K25*P25 -> 14639789 | M25: =I25/P25 -> 1643.46 | N25: =M25*P25 -> 16566077 | O25: =P25-G25 -> 18 | P25: =Q25*R25 -> 10080 | Q25: 56 | R25: 180 | S25: 1683355 | T25: ЛУКОЙЛ КАРБОФЛЕКС OG 000-1500 HD | U25: замена фасовки 18 кг на 180 кг
A26: 0.51 | B26: 10041102 | C26: LEMARC GREASEGUARD MS EP 1 / LEMARC GREASEGUARD MS EP 1 | D26: кг | E26: 180 | F26: 71 | G26: 12780 | H26: 1222.2 | I26: =G26*H26 -> 15619716 | K26: =M26*0.98 -> 1197.756 | L26: =K26*P26 -> 15307322 | M26: =I26/P26 -> 1222.2 | N26: =M26*P26 -> 15619716 | O26: =P26-G26 -> 0 | P26: =Q26*R26 -> 12780 | Q26: 71 | R26: 180 | S26: 1615722 | T26: ЛУКОЙЛ ПОЛИФЛЕКС ЕР 1-160 HD
A27: 0.52 | B27: 15000022 | C27: LEMARC GREASEGUARD MS EP1 / LEMARC GREASEGUARD MS EP1 | D27: кг | E27: 0.375 | F27: 11264 | G27: 4224 | H27: 1601.34 | I27: =G27*H27 -> 6764060.2 | K27: =M27*0.98 -> 1569.3132 | L27: =K27*P27 -> 6628779 | M27: =I27/P27 -> 1601.34 | N27: =M27*P27 -> 6764060.2 | O27: =P27-G27 -> 0 | P27: =Q27*R27 -> 4224 | Q27: 10560 | R27: 0.4 | S27: 1615401 | T27: ЛУКОЙЛ ПОЛИФЛЕКС ЕР 1-160 HD
A28: 0.53 | B28: 15000024 | C28: LEMARC GREASEGUARD MS EP 0/00 / LEMARC GREASEGUARD MS EP 0/00 | D28: кг | E28: 180 | F28: 164 | G28: 29520 | H28: 1507.44 | I28: =G28*H28 -> 44499629 | K28: =M28*0.98 -> 1477.2912 | L28: =K28*P28 -> 43609636 | M28: =I28/P28 -> 1507.44 | N28: =M28*P28 -> 44499629 | O28: =P28-G28 -> 0 | P28: =Q28*R28 -> 29520 | Q28: 164 | R28: 180 | S28: 1755295 | T28: ЛУКОЙЛ СИНТОФЛЕКС АРКТИК 1-100 HD - всесезонно/all season
A29: 0.54 | B29: 15000023 | C29: LEMARC GREASEGUARD MS EP 0/00 / LEMARC GREASEGUARD MS EP 0/00 | D29: кг | E29: 18 | F29: 559 | G29: 10062 | H29: 1595.5 | I29: =G29*H29 -> 16053921 | K29: =M29*0.98 -> 1563.59 | L29: =K29*P29 -> 15732843 | M29: =I29/P29 -> 1595.5 | N29: =M29*P29 -> 16053921 | O29: =P29-G29 -> 0 | P29: =Q29*R29 -> 10062 | Q29: 559 | R29: 18 | S29: 1748233 | T29: ЛУКОЙЛ СИНТОФЛЕКС АРКТИК 1-100 HD - всесезонно/all season
A30: 0.55 | B30: 14220301 | C30: LEMARC FFD / LEMARC FFD | D30: л | E30: 1 | F30: 100 | G30: 100 | H30: 3207.6 | I30: =G30*H30 -> 320760 | K30: =M30 -> 3207.6 | L30: =K30*P30 -> 320760 | M30: =I30/P30 -> 3207.6 | N30: =M30*P30 -> 320760 | O30: =P30-G30 -> 0 | P30: =Q30*R30 -> 100 | Q30: 100 | R30: 1 | S30: 14220301 | T30: LEMARC FFD / LEMARC FFD
A31: 0.56 | B31: 14240401 | C31: LEMARC WINDGUARD 50 / LEMARC WINDGUARD 50 | D31: л | E31: 2 | F31: 500 | G31: 1000 | H31: 297 | I31: =G31*H31 -> 297000 | K31: =M31 -> 297 | L31: =K31*P31 -> 297000 | M31: =I31/P31 -> 297 | N31: =M31*P31 -> 297000 | O31: =P31-G31 -> 0 | P31: =Q31*R31 -> 1000 | Q31: 500 | R31: 2 | S31: 14240401 | T31: LEMARC WINDGUARD 50 / LEMARC WINDGUARD 50
A32: 0.57 | B32: 10050303 | C32: LEMARC DOT4 Low Temp / LEMARC DOT4 Low Temp | D32: л | E32: 1 | F32: 1489 | G32: 1489 | H32: 481.14 | I32: =G32*H32 -> 716417.46 | K32: =M32 -> 481.14 | L32: =K32*P32 -> 716417.46 | M32: =I32/P32 -> 481.14 | N32: =M32*P32 -> 716417.46 | O32: =P32-G32 -> 0 | P32: =Q32*R32 -> 1489 | Q32: 1489 | R32: 1 | S32: 10050303 | T32: LEMARC DOT4 Low Temp / LEMARC DOT4 Low Temp
I33: =SUM(I4:I32) -> 7.6685217e+08 | L33: =SUM(L4:L32) -> 7.6155814e+08 | N33: =SUM(N4:N32) -> 7.6685217e+08
J35: Дельта | K35: =I33-L33 -> 5294027.9

Sheet Specification 02 rev CO-05
A2: REV CO-04 | L2: REV CO-05
A3: Oils and Technical Fluids for 2027 season | E3: Site use | F3: Self-performed Maintenance | L3: Oils and Technical Fluids for 2027 season | P3: Site use | Q3: Self-performed Maintenance
A4: Масла и технические жидкости на 2027 г. | E4: area: | L4: Масла и технические жидкости на 2027 г. | P4: area:
A5: PR No.: | E5: WBS | F5: 8260 | G5: Contractor ID: | H5: CC-419 | L5: PR No.: | P5: WBS | Q5: 8260 | R5: Contractor ID: | S5: CC-419
E6: Code(s): | P6: Code(s):
A7: № | B7: Equipment / | C7: Line Item Description / | D7: Q-ty / | E7: UOM / | F7: Unit price w/o VAT / Цена за ед. не вкл. НДС | G7: Total price / | H7: Date for Delivery / Дата Поставки | L7: № | M7: Equipment / | N7: Line Item Description / | O7: Q-ty / | P7: UOM / | Q7: Unit price w/o VAT / Цена за ед. не вкл. НДС | R7: Total price / | S7: Date for Delivery / Дата Поставки
B8: Material ID | C8: Наименование позиции | D8: Кол-во. | E8: Ед. изм | G8: Сумма | M8: Material ID | N8: Наименование позиции | O8: Кол-во. | P8: Ед. изм | R8: Сумма
F9: Rub./Руб | G9: Rub./Руб | Q9: Rub./Руб | R9: Rub./Руб | W9: CHANGE? ADDED TO CORF?
A10: 0.26 | B10: 10081103 | C10: АНТИФРИЗ LEMARC FROSTGUARD G12+ Extra / ANTIFREEZE LEMARC FROSTGUARD G12+ Extra | D10: 100464 | E10: liter / литры | F10: 176.75 | G10: 17757012 | H10: 46174 | J10: =B10='Products for specification 2'!S4 -> TRUE | L10: 0.26 | M10: 10081103 | N10: АНТИФРИЗ LEMARC FROSTGUARD G12+ Extra / ANTIFREEZE LEMARC FROSTGUARD G12+ Extra | O10: 100464 | P10: liter / литры | Q10: 176.75 | R10: =ROUND(O10*Q10,2) -> 17757012 | S10: 46174 | U10: =M10='Products for specification 2'!S4 -> TRUE | V10: =O10='Products for specification 2'!P4 -> TRUE | W10: YES
A11: 0.27 | B11: 13621101 | C11: МАСЛО LEMARC AEROGUARD SH 46 / LEMARC AEROGUARD SH 46 OIL | D11: 20176 | E11: liter / литры | F11: 200.36 | G11: 4042463.4 | H11: 46174 | J11: =B11='Products for specification 2'!S5 -> TRUE | L11: 0.27 | M11: 13621101 | N11: МАСЛО LEMARC AEROGUARD SH 46 / LEMARC AEROGUARD SH 46 OIL | O11: 20176 | P11: liter / литры | Q11: 200.36 | R11: =ROUND(O11*Q11,2) -> 4042463.4 | S11: 46174 | U11: =M11='Products for specification 2'!S5 -> TRUE | V11: =O11='Products for specification 2'!P5 -> TRUE
A12: 0.28 | B12: 14021101 | C12: МАСЛО LEMARC PNEUMOGUARD 100 / LEMARC PNEUMOGUARD 100 OIL | D12: 1664 | E12: liter / литры | F12: 176.75 | G12: 294112 | H12: 46174 | J12: =B12='Products for specification 2'!S6 -> TRUE | L12: 0.28 | M12: 14021101 | N12: МАСЛО LEMARC PNEUMOGUARD 100 / LEMARC PNEUMOGUARD 100 OIL | O12: 1664 | P12: liter / литры | Q12: 176.75 | R12: =ROUND(O12*Q12,2) -> 294112 | S12: 46174 | U12: =M12='Products for specification 2'!S6 -> TRUE | V12: =O12='Products for specification 2'!P6 -> TRUE
A13: 0.29 | B13: 14111101 | C13: МАСЛО LEMARC PNEUMOGUARD 32 / LEMARC PNEUMOGUARD 32 OIL | D13: 4160 | E13: liter / литры | F13: 159.23 | G13: 662396.8 | H13: 46174 | J13: =B13='Products for specification 2'!S7 -> TRUE | L13: 0.29 | M13: 14111101 | N13: МАСЛО LEMARC PNEUMOGUARD 32 / LEMARC PNEUMOGUARD 32 OIL | O13: 4160 | P13: liter / литры | Q13: 159.23 | R13: =ROUND(O13*Q13,2) -> 662396.8 | S13: 46174 | U13: =M13='Products for specification 2'!S7 -> TRUE | V13: =O13='Products for specification 2'!P7 -> TRUE
A14: 0.30 | B14: 12001101 | C14: Трансмиссионная жидкость LEMARC GEAPARD DVI LV / LEMARC GEAPARD DVI LV Transmission Fluid | D14: 6448 | E14: liter / литры | F14: 328.85 | G14: 2120424.8 | H14: 46174 | J14: =B14='Products for specification 2'!S8 -> TRUE | L14: 0.30 | M14: 12001101 | N14: Трансмиссионная жидкость LEMARC GEAPARD DVI LV / LEMARC GEAPARD DVI LV Transmission Fluid | O14: 6448 | P14: liter / литры | Q14: 328.85 | R14: =ROUND(O14*Q14,2) -> 2120424.8 | S14: 46174 | U14: =M14='Products for specification 2'!S8 -> TRUE | V14: =O14='Products for specification 2'!P8 -> TRUE
A15: 0.31 | B15: 11951101 | C15: МАСЛО LEMARC GEAPARD X4/X5 75W90 / LEMARC GEAPARD X4/X5 75W90 OIL | D15: 147056 | E15: liter / литры | F15: 600.42 | G15: 88295364 | H15: 46174 | J15: =B15='Products for specification 2'!S9 -> FALSE | L15: 0.31 | M15: ='Products for specification 2'!S9 -> 1495990 | N15: ="Масло"&" "&'Products for specification 2'!T9&" / "&'Products for specification 2'!T9 -> Масло TEBOIL HYPOID 75W90 / TEBOIL HYPOID 75W90 | O15: ='[1]Products for specification 2'!P9 -> 147159 | P15: liter / литры | Q15: ='[1]Products for specification 2'!M9 -> 599.99975 | R15: =ROUND(O15*Q15,2) -> 88295364 | S15: 46174 | U15: =M15='Products for specification 2'!S9 -> TRUE | V15: =O15='Products for specification 2'!P9 -> TRUE | W15: YES
A16: 0.32 | B16: 14121101 | C16: МАСЛО LEMARC GEAPARD X5 75W140 / LEMARC GEAPARD X5 75W140 OIL | D16: 44304 | E16: liter / литры | F16: 501.38 | G16: 22213140 | H16: 46174 | J16: =B16='Products for specification 2'!S10 -> TRUE | L16: 0.32 | M16: 14121101 | N16: МАСЛО LEMARC GEAPARD X5 75W140 / LEMARC GEAPARD X5 75W140 OIL | O16: 44304 | P16: liter / литры | Q16: 501.38 | R16: =ROUND(O16*Q16,2) -> 22213140 | S16: 46174 | U16: =M16='Products for specification 2'!S10 -> TRUE | V16: =O16='Products for specification 2'!P10 -> TRUE
A17: 0.34 | B17: 14131101 | C17: МАСЛО LEMARC LEGUARD MPV LT / LEMARC LEGUARD MPV LT OIL | D17: 48880 | E17: liter / литры | F17: 187.83 | G17: 9181130.4 | H17: 46174 | J17: =B17='Products for specification 2'!S11 -> TRUE | L17: 0.34 | M17: 14131101 | N17: МАСЛО LEMARC LEGUARD MPV LT / LEMARC LEGUARD MPV LT OIL | O17: 48880 | P17: liter / литры | Q17: 187.83 | R17: =ROUND(O17*Q17,2) -> 9181130.4 | S17: 46174 | U17: =M17='Products for specification 2'!S11 -> TRUE | V17: =O17='Products for specification 2'!P11 -> TRUE
A18: 0.35 | B18: 14141101 | C18: МАСЛО LEMARC LEGUARD AC 5W30 / LEMARC LEGUARD AC 5W30 OIL | D18: 105664 | E18: liter / литры | F18: 292.07 | G18: 30861284 | H18: 46174 | J18: =B18='Products for specification 2'!S12 -> TRUE | L18: 0.35 | M18: 14141101 | N18: МАСЛО LEMARC LEGUARD AC 5W30 / LEMARC LEGUARD AC 5W30 OIL | O18: 105664 | P18: liter / литры | Q18: 292.07 | R18: =ROUND(O18*Q18,2) -> 30861284 | S18: 46174 | U18: =M18='Products for specification 2'!S12 -> TRUE | V18: =O18='Products for specification 2'!P12 -> TRUE
A19: 0.36 | B19: 14151101 | C19: МАСЛО LEMARC LEGUARD 40 0W40 / LEMARC LEGUARD 40 0W40 OIL | D19: 636688 | E19: liter / литры | F19: 545.19 | G19: 3.4711593e+08 | H19: 46174 | J19: =B19='Products for specification 2'!S13 -> TRUE | L19: 0.36 | M19: 14151101 | N19: МАСЛО LEMARC LEGUARD 40 0W40 / LEMARC LEGUARD 40 0W40 OIL | O19: 636688 | P19: liter / литры | Q19: 545.19 | R19: =ROUND(O19*Q19,2) -> 3.4711593e+08 | S19: 46174 | U19: =M19='Products for specification 2'!S13 -> TRUE | V19: =O19='Products for specification 2'!P13 -> TRUE
A20: 0.37 | B20: 14161101 | C20: МАСЛО LEMARC CARTERRA SH 150 / LEMARC CARTERRA SH 150 OIL | D20: 26832 | E20: liter / литры | F20: 530.05 | G20: 14222302 | H20: 46174 | J20: =B20='Products for specification 2'!S14 -> TRUE | L20: 0.37 | M20: 14161101 | N20: МАСЛО LEMARC CARTERRA SH 150 / LEMARC CARTERRA SH 150 OIL | O20: 26832 | P20: liter / литры | Q20: 530.05 | R20: =ROUND(O20*Q20,2) -> 14222302 | S20: 46174 | U20: =M20='Products for specification 2'!S14 -> TRUE | V20: =O20='Products for specification 2'!P14 -> TRUE
A21: 0.38 | B21: 14171101 | C21: МАСЛО LEMARC CARTERRA SH 220 / LEMARC CARTERRA SH 220 OIL | D21: 7072 | E21: liter / литры | F21: 551.25 | G21: 3898440 | H21: 46174 | J21: =B21='Products for specification 2'!S15 -> TRUE | L21: 0.38 | M21: 14171101 | N21: МАСЛО LEMARC CARTERRA SH 220 / LEMARC CARTERRA SH 220 OIL | O21: 7072 | P21: liter / литры | Q21: 551.25 | R21: =ROUND(O21*Q21,2) -> 3898440 | S21: 46174 | U21: =M21='Products for specification 2'!S15 -> TRUE | V21: =O21='Products for specification 2'!P15 -> TRUE
A22: 0.39 | B22: 14181101 | C22: МАСЛО LEMARC CARTERRA SH 680 / LEMARC CARTERRA SH 680 OIL | D22: 14144 | E22: liter / литры | F22: 686.05 | G22: 9703491.2 | H22: 46174 | J22: =B22='Products for specification 2'!S16 -> FALSE | L22: 0.39 | M22: ='Products for specification 2'!S16 -> 3475721 | N22: ="Масло"&" "&'Products for specification 2'!T16&" / "&'Products for specification 2'!T16 -> Масло TEBOIL SYPRES EXTRA 680 / TEBOIL SYPRES EXTRA 680 | O22: ='[1]Products for specification 2'!P16 -> 14205.72 | P22: liter / литры | Q22: ='[1]Products for specification 2'!M16 -> 683.0693 | R22: =ROUND(O22*Q22,2) -> 9703491.2 | S22: 46174 | U22: =M22='Products for specification 2'!S16 -> TRUE | V22: =O22='Products for specification 2'!P16 -> TRUE | W22: YES
A23: 0.40 | B23: 12311101 | C23: МАСЛО LEMARC HYDRARD XV32 / LEMARC HYDRARD XV32 OIL | D23: 1872 | E23: liter / литры | F23: 267.19 | G23: 500179.68 | H23: 46174 | J23: =B23='Products for specification 2'!S17 -> TRUE | L23: 0.40 | M23: 12311101 | N23: МАСЛО LEMARC HYDRARD XV32 / LEMARC HYDRARD XV32 OIL | O23: 1872 | P23: liter / литры | Q23: 267.19 | R23: =ROUND(O23*Q23,2) -> 500179.68 | S23: 46174 | U23: =M23='Products for specification 2'!S17 -> TRUE | V23: =O23='Products for specification 2'!P17 -> TRUE
A24: 0.41 | B24: 14191101 | C24: МАСЛО LEMARC HYDRARD HVLP-ZF LT 32 / LEMARC HYDRARD HVLP-ZF LT 32 OIL | D24: 285584 | E24: liter / литры | F24: 174.7 | G24: 49891525 | H24: 46174 | J24: =B24='Products for specification 2'!S18 -> TRUE | L24: 0.41 | M24: 14191101 | N24: МАСЛО LEMARC HYDRARD HVLP-ZF LT 32 / LEMARC HYDRARD HVLP-ZF LT 32 OIL | O24: 285584 | P24: liter / литры | Q24: 174.7 | R24: =ROUND(O24*Q24,2) -> 49891525 | S24: 46174 | U24: =M24='Products for specification 2'!S18 -> TRUE | V24: =O24='Products for specification 2'!P18 -> TRUE
A25: 0.42 | B25: 10161102 | C25: СМАЗКА LEMARC GREGUARD EP 0 / LEMARC GREGUARD EP 0 GREASE | D25: 19260 | E25: kg /кг | F25: 467.09 | G25: 8996153.4 | H25: 46174 | J25: =B25='Products for specification 2'!S19 -> FALSE | L25: 0.42 | M25: ='Products for specification 2'!S19 -> 1558960 | N25: ="Смазка"&" "&'Products for specification 2'!T19&" / "&'Products for specification 2'!T19 -> Смазка ЛУКОЙЛ ПОЛИФЛЕКС ЕР 0-160 / ЛУКОЙЛ ПОЛИФЛЕКС ЕР 0-160 | O25: ='[1]Products for specification 2'!P19 -> 19260 | P25: kg /кг | Q25: ='[1]Products for specification 2'!M19 -> 467.09 | R25: =ROUND(O25*Q25,2) -> 8996153.4 | S25: 46174 | U25: =M25='Products for specification 2'!S19 -> TRUE | V25: =O25='Products for specification 2'!P19 -> TRUE | W25: YES
A26: 0.43 | B26: 10171102 | C26: СМАЗКА LEMARC GREGUARD EP 1 / LEMARC GREGUARD EP 1 GREASE | D26: 44820 | E26: kg /кг | F26: 450.6 | G26: 20195892 | H26: 46174 | J26: =B26='Products for specification 2'!S20 -> FALSE | L26: 0.43 | M26: ='Products for specification 2'!S20 -> 1558966 | N26: ="Смазка"&" "&'Products for specification 2'!T20&" / "&'Products for specification 2'!T20 -> Смазка ЛУКОЙЛ ПОЛИФЛЕКС ЕР 1-160 / ЛУКОЙЛ ПОЛИФЛЕКС ЕР 1-160 | O26: ='[1]Products for specification 2'!P20 -> 44820 | P26: kg /кг | Q26: ='[1]Products for specification 2'!M20 -> 450.6 | R26: =ROUND(O26*Q26,2) -> 20195892 | S26: 46174 | U26: =M26='Products for specification 2'!S20 -> TRUE | V26: =O26='Products for specification 2'!P20 -> TRUE | W26: YES
A27: 0.44 | B27: 10131102 | C27: СМАЗКА LEMARC GREGUARD OG EP 0 / LEMARC GREGUARD OG EP 0 GREASE | D27: 10620 | E27: kg /кг | F27: 1539 | G27: 16344180 | H27: 46174 | J27: =B27='Products for specification 2'!S21 -> FALSE | L27: 0.44 | M27: ='Products for specification 2'!S21 -> 1682082 | N27: ="Смазка"&" "&'Products for specification 2'!T21&" / "&'Products for specification 2'!T21 -> Смазка ЛУКОЙЛ КАРБОФЛЕКС OG 0-4000 HD / ЛУКОЙЛ КАРБОФЛЕКС OG 0-4000 HD | O27: ='[1]Products for specification 2'!P21 -> 10620 | P27: kg /кг | Q27: ='[1]Products for specification 2'!M21 -> 1539 | R27: =ROUND(O27*Q27,2) -> 16344180 | S27: 46174 | U27: =M27='Products for specification 2'!S21 -> TRUE | V27: =O27='Products for specification 2'!P21 -> TRUE | W27: YES
A28: 0.46 | B28: 10181102 | C28: СМАЗКА LEMARC GREGUARD MS EP 2 / LEMARC GREGUARD MS EP 2 GREASE | D28: 900 | E28: kg /кг | F28: 1160.27 | G28: 1044243 | H28: 46174 | J28: =B28='Products for specification 2'!S22 -> FALSE | L28: 0.46 | M28: ='Products for specification 2'!S22 -> 1559874 | N28: ="Смазка"&" "&'Products for specification 2'!T22&" / "&'Products for specification 2'!T22 -> Смазка ЛУКОЙЛ ПОЛИФЛЕКС ЕР 2-160 HD / ЛУКОЙЛ ПОЛИФЛЕКС ЕР 2-160 HD | O28: ='[1]Products for specification 2'!P22 -> 900 | P28: kg /кг | Q28: ='[1]Products for specification 2'!M22 -> 1160.27 | R28: =ROUND(O28*Q28,2) -> 1044243 | S28: 46174 | U28: =M28='Products for specification 2'!S22 -> TRUE | V28: =O28='Products for specification 2'!P22 -> TRUE | W28: YES
A29: 0.48 | B29: 10130902 | C29: СМАЗКА LEMARC GREGUARD OG EP 0 / LEMARC GREGUARD OG EP 0 GREASE | D29: 2160 | E29: kg /кг | F29: 1729.8 | G29: 3736368 | H29: 46174 | J29: =B29='Products for specification 2'!S23 -> FALSE | L29: 0.48 | M29: ='Products for specification 2'!S23 -> 1682082 | N29: ="Смазка"&" "&'Products for specification 2'!T23&" / "&'Products for specification 2'!T23 -> Смазка ЛУКОЙЛ КАРБОФЛЕКС OG 0-4000 HD / ЛУКОЙЛ КАРБОФЛЕКС OG 0-4000 HD | O29: ='[1]Products for specification 2'!P23 -> 2160 | P29: kg /кг | Q29: ='[1]Products for specification 2'!M23 -> 1729.8 | R29: =ROUND(O29*Q29,2) -> 3736368 | S29: 46174 | U29: =M29='Products for specification 2'!S23 -> TRUE | V29: =O29='Products for specification 2'!P23 -> TRUE | W29: YES
A30: 0.49 | B30: 10141102 | C30: СМАЗКА LEMARC GREGUARD OG EP 000 / LEMARC GREGUARD OG EP 000 GREASE | D30: 10080 | E30: kg /кг | F30: 1482 | G30: 14938560 | H30: 46174 | J30: =B30='Products for specification 2'!S24 -> FALSE | L30: 0.49 | M30: ='Products for specification 2'!S24 -> 1683355 | N30: ="Смазка"&" "&'Products for specification 2'!T24&" / "&'Products for specification 2'!T24 -> Смазка ЛУКОЙЛ КАРБОФЛЕКС OG 000-1500 HD / ЛУКОЙЛ КАРБОФЛЕКС OG 000-1500 HD | O30: ='[1]Products for specification 2'!P24 -> 10080 | P30: kg /кг | Q30: ='[1]Products for specification 2'!M24 -> 1482 | R30: =ROUND(O30*Q30,2) -> 14938560 | S30: 46174 | U30: =M30='Products for specification 2'!S24 -> TRUE | V30: =O30='Products for specification 2'!P24 -> TRUE | W30: YES
A31: 0.50 | B31: 10140902 | C31: СМАЗКА LEMARC GREGUARD OG EP 000 / LEMARC GREGUARD OG EP 000 GREASE | D31: 10062 | E31: kg /кг | F31: 1646.4 | G31: 16566077 | H31: 46174 | J31: =B31='Products for specification 2'!S25 -> FALSE | L31: 0.50 | M31: ='Products for specification 2'!S25 -> 1683355 | N31: ="Смазка"&" "&'Products for specification 2'!T25&" / "&'Products for specification 2'!T25 -> Смазка ЛУКОЙЛ КАРБОФЛЕКС OG 000-1500 HD / ЛУКОЙЛ КАРБОФЛЕКС OG 000-1500 HD | O31: ='[1]Products for specification 2'!P25 -> 10080 | P31: kg /кг | Q31: ='[1]Products for specification 2'!M25 -> 1643.46 | R31: =ROUND(O31*Q31,2) -> 16566077 | S31: 46174 | U31: =M31='Products for specification 2'!S25 -> TRUE | V31: =O31='Products for specification 2'!P25 -> TRUE | W31: YES
A32: 0.51 | B32: 10151102 | C32: СМАЗКА LEMARC GREGUARD MS EP 1 / LEMARC GREGUARD MS EP 1 GREASE | D32: 12780 | E32: kg /кг | F32: 1222.2 | G32: 15619716 | H32: 46174 | J32: =B32='Products for specification 2'!S26 -> FALSE | L32: 0.51 | M32: ='Products for specification 2'!S26 -> 1615722 | N32: ="Смазка"&" "&'Products for specification 2'!T26&" / "&'Products for specification 2'!T26 -> Смазка ЛУКОЙЛ ПОЛИФЛЕКС ЕР 1-160 HD / ЛУКОЙЛ ПОЛИФЛЕКС ЕР 1-160 HD | O32: ='[1]Products for specification 2'!P26 -> 12780 | P32: kg /кг | Q32: ='[1]Products for specification 2'!M26 -> 1222.2 | R32: =ROUND(O32*Q32,2) -> 15619716 | S32: 46174 | U32: =M32='Products for specification 2'!S26 -> TRUE | V32: =O32='Products for specification 2'!P26 -> TRUE | W32: YES
A33: 0.52 | B33: 10150202 | C33: СМАЗКА LEMARC GREGUARD MS EP 1 / LEMARC GREGUARD MS EP 1 | D33: 4224 | E33: kg /кг | F33: 1601.34 | G33: 6764060.2 | H33: 46174 | J33: =B33='Products for specification 2'!S27 -> FALSE | L33: 0.52 | M33: ='Products for specification 2'!S27 -> 1615401 | N33: ="Смазка"&" "&'Products for specification 2'!T27&" / "&'Products for specification 2'!T27 -> Смазка ЛУКОЙЛ ПОЛИФЛЕКС ЕР 1-160 HD / ЛУКОЙЛ ПОЛИФЛЕКС ЕР 1-160 HD | O33: ='[1]Products for specification 2'!P27 -> 4224 | P33: kg /кг | Q33: ='[1]Products for specification 2'!M27 -> 1601.34 | R33: =ROUND(O33*Q33,2) -> 6764060.2 | S33: 46174 | U33: =M33='Products for specification 2'!S27 -> TRUE | V33: =O33='Products for specification 2'!P27 -> TRUE | W33: YES
A34: 0.53 | B34: 10191102 | C34: СМАЗКА LEMARC GREGUARD MS EP 0/00 / LEMARC GREGUARD MS EP 0/00 LUBRICANT | D34: 29520 | E34: kg /кг | F34: 1507.44 | G34: 44499629 | H34: 46174 | J34: =B34='Products for specification 2'!S28 -> FALSE | L34: 0.53 | M34: ='Products for specification 2'!S28 -> 1755295 | N34: ="Смазка"&" "&'Products for specification 2'!T28&" / "&'Products for specification 2'!T28 -> Смазка ЛУКОЙЛ СИНТОФЛЕКС АРКТИК 1-100 HD - всесезонно/all season / ЛУКОЙЛ СИНТОФЛЕКС АРКТИК 1-100 HD - всесезонно/all season | O34: ='[1]Products for specification 2'!P28 -> 29520 | P34: kg /кг | Q34: ='[1]Products for specification 2'!M28 -> 1507.44 | R34: =ROUND(O34*Q34,2) -> 44499629 | S34: 46174 | U34: =M34='Products for specification 2'!S28 -> TRUE | V34: =O34='Products for specification 2'!P28 -> TRUE | W34: YES
A35: 0.54 | B35: 10190902 | C35: СМАЗКА LEMARC GREGUARD MS EP 0/00 / LEMARC GREGUARD MS EP 0/00 LUBRICANT | D35: 10062 | E35: kg /кг | F35: 1595.5 | G35: 16053921 | H35: 46174 | J35: =B35='Products for specification 2'!S29 -> FALSE | L35: 0.54 | M35: ='Products for specification 2'!S29 -> 1748233 | N35: ="Смазка"&" "&'Products for specification 2'!T29&" / "&'Products for specification 2'!T29 -> Смазка ЛУКОЙЛ СИНТОФЛЕКС АРКТИК 1-100 HD - всесезонно/all season / ЛУКОЙЛ СИНТОФЛЕКС АРКТИК 1-100 HD - всесезонно/all season | O35: ='[1]Products for specification 2'!P29 -> 10062 | P35: kg /кг | Q35: ='[1]Products for specification 2'!M29 -> 1595.5 | R35: =ROUND(O35*Q35,2) -> 16053921 | S35: 46174 | U35: =M35='Products for specification 2'!S29 -> TRUE | V35: =O35='Products for specification 2'!P29 -> TRUE | W35: YES
A36: 0.55 | B36: 14220301 | C36: АНТИФРИЗ LEMARC FFD / LEMARC FFD ANTIFREEZE | D36: 100 | E36: liter / литры | F36: 3207.6 | G36: 320760 | H36: 46174 | J36: =B36='Products for specification 2'!S30 -> TRUE | L36: 0.55 | M36: 14220301 | N36: АНТИФРИЗ LEMARC FFD / LEMARC FFD ANTIFREEZE | O36: 100 | P36: liter / литры | Q36: 3207.6 | R36: =ROUND(O36*Q36,2) -> 320760 | S36: 46174 | U36: =M36='Products for specification 2'!S30 -> TRUE | V36: =O36='Products for specification 2'!P30 -> TRUE
A37: 0.56 | B37: 14240401 | C37: ЖИДКОСТЬ СТЕКЛООМЫВАТЕЛЯ LEMARC WINDGUARD 50 / LEMARC WINDGUARD 50 WINDSHIELD WASHER FLUID | D37: 1000 | E37: liter / литры | F37: 297 | G37: 297000 | H37: 46174 | J37: =B37='Products for specification 2'!S31 -> TRUE | L37: 0.56 | M37: 14240401 | N37: ЖИДКОСТЬ СТЕКЛООМЫВАТЕЛЯ LEMARC WINDGUARD 50 / LEMARC WINDGUARD 50 WINDSHIELD WASHER FLUID | O37: 1000 | P37: liter / литры | Q37: 297 | R37: =ROUND(O37*Q37,2) -> 297000 | S37: 46174 | U37: =M37='Products for specification 2'!S31 -> TRUE | V37: =O37='Products for specification 2'!P31 -> TRUE
A38: 0.57 | B38: 10050303 | C38: Тормозная жидкость LEMARC DOT4 Low Temp / LEMARC DOT4 Low Temp Brake Fluid | D38: 1489 | E38: liter / литры | F38: 481.14 | G38: 716417.46 | H38: 46174 | J38: =B38='Products for specification 2'!S32 -> TRUE | L38: 0.57 | M38: 10050303 | N38: Тормозная жидкость LEMARC DOT4 Low Temp / LEMARC DOT4 Low Temp Brake Fluid | O38: 1489 | P38: liter / литры | Q38: 481.14 | R38: =ROUND(O38*Q38,2) -> 716417.46 | S38: 46174 | U38: =M38='Products for specification 2'!S32 -> TRUE | V38: =O38='Products for specification 2'!P32 -> TRUE
A39: Total amount w/o VAT / Итого, не вкл. НДС: | F39: 7.6685217e+08 | H39: Rub./Руб | L39: Total amount w/o VAT / Итого, не вкл. НДС: | Q39: =SUM(R10:R38) -> 7.6685217e+08 | S39: Rub./Руб
A40: In addition, VAT 22% / Кроме того НДС 22%: | F40: 1.6870748e+08 | H40: Rub./Руб | L40: In addition, VAT 22% / Кроме того НДС 22%: | Q40: =Q39*0.22 -> 1.6870748e+08 | S40: Rub./Руб
A41: Total Amount in inclusive of VAT / Итого, c учетом НДС: | F41: 9.2022261e+08 | H41: Rub./Руб | L41: Total Amount in inclusive of VAT / Итого, c учетом НДС: | Q41: =Q39+Q40 -> 9.3555965e+08 | S41: Rub./Руб
...

Sheet График
I1: недели
I2: июль | L2: август | P2: сентябрь
A3: TAG # | B3: SKU / Артикул | C3: Предлагаемый к поставке в 2026 году продукт | D3: ед. изм | E3: Общее кол-во продукта | F3: Кол-во тары | G3: Л/КГ В БОЧКЕ | I3: 29 | J3: 30 | K3: 31 | L3: 32 | M3: 33 | N3: 34 | O3: 35 | P3: 36 (резерв) | Q3: Итого
A4: 0.26 | B4: 10081103 | C4: LEMARC FROSTGUARD G12+ Extra / LEMARC FROSTGUARD G12+ Extra | D4: л | E4: 100464 | F4: 483 | G4: 208 | J4: 40000 | K4: 40000 | L4: 20464 | Q4: =SUM(I4:P4) -> 100464
A5: 0.27 | B5: 13621101 | C5: LEMARC AEROGUARD SH 46 / LEMARC AEROGUARD SH 46 | D5: л | E5: 20176 | F5: 97 | G5: 208 | J5: =E5 -> 20176 | Q5: =SUM(I5:P5) -> 20176
A6: 0.28 | B6: 14021101 | C6: LEMARC PNEUMOGUARD 100 / LEMARC PNEUMOGUARD 100 | D6: л | E6: 1664 | F6: 8 | G6: 208 | J6: =E6 -> 1664 | Q6: =SUM(I6:P6) -> 1664
A7: 0.29 | B7: 14111101 | C7: LEMARC PNEUMOGUARD 32 / LEMARC PNEUMOGUARD 32 OIL | D7: л | E7: 4160 | F7: 20 | G7: 208 | K7: 4160 | Q7: =SUM(I7:P7) -> 4160
A8: 0.30 | B8: 12001101 | C8: LEMARC GEAPARD DVI LV / LEMARC GEAPARD DVI LV | D8: л | E8: 6448 | F8: 31 | G8: 208 | J8: =E8 -> 6448 | Q8: =SUM(I8:P8) -> 6448
A9: 0.31 | B9: 1495990 | C9: TEBOIL HYPOID 75W90 | D9: л | E9: 147159 | F9: 747 | G9: 197 | N9: =E9/2 -> 73579.5 | O9: =N9 -> 73579.5 | Q9: =SUM(I9:P9) -> 147159
A10: 0.32 | B10: 14121101 | C10: LEMARC GEAPARD X5 75W140 / LEMARC GEAPARD X5 75W140 | D10: л | E10: 44304 | F10: 213 | G10: 208 | J10: =E10/2 -> 22152 | K10: =J10 -> 22152 | Q10: =SUM(I10:P10) -> 44304
A11: 0.34 | B11: 14131101 | C11: LEMARC LEGUARD MPV LT / LEMARC LEGUARD MPV LT | D11: л | E11: 48880 | F11: 235 | G11: 208 | J11: 24440 | K11: 24440 | Q11: =SUM(I11:P11) -> 48880
A12: 0.35 | B12: 14141101 | C12: LEMARC LEGUARD AC 5W30 / LEMARC LEGUARD AC 5W30 | D12: л | E12: 105664 | F12: 508 | G12: 208 | K12: =L12 -> 35221.333 | L12: =E12/3 -> 35221.333 | M12: =L12 -> 35221.333 | Q12: =SUM(I12:P12) -> 105664
A13: 0.36 | B13: 14151101 | C13: LEMARC LEGUARD 40 0W40 / LEMARC LEGUARD 40 0W40 | D13: л | E13: 636688 | F13: 3061 | G13: 208 | L13: =E13/4 -> 159172 | M13: =L13 -> 159172 | N13: =M13 -> 159172 | O13: =N13 -> 159172 | Q13: =SUM(I13:P13) -> 636688
A14: 0.37 | B14: 14161101 | C14: LEMARC CARTERRA SH 150/ LEMARC CARTERRA SH 150 | D14: л | E14: 26832 | F14: 129 | G14: 208 | K14: =E14 -> 26832 | Q14: =SUM(I14:P14) -> 26832
A15: 0.38 | B15: 14171101 | C15: LEMARC CARTERRA SH 220 / LEMARC CARTERRA SH 220 | D15: л | E15: 7072 | F15: 34 | G15: 208 | J15: =E15 -> 7072 | Q15: =SUM(I15:P15) -> 7072
A16: 0.39 | B16: 3475721 | C16: TEBOIL SYPRES EXTRA 680 | D16: л | E16: 14205.72 | F16: 69 | G16: 205.88 | L16: =E16 -> 14205.72 | Q16: =SUM(I16:P16) -> 14205.72
A17: 0.40 | B17: 12311101 | C17: LEMARC HYDRARD XV 32 / LEMARC HYDRARD XV 32 | D17: л | E17: 1872 | F17: 9 | G17: 208 | J17: =E17 -> 1872 | Q17: =SUM(I17:P17) -> 1872
A18: 0.41 | B18: 14191101 | C18: LEMARC HYDRARD HVLP-ZF LT 32 / LEMARC HYDRARD HVLP-ZF LT 32 | D18: л | E18: 285584 | F18: 1373 | G18: 208 | K18: =E18/4 -> 71396 | L18: =K18 -> 71396 | M18: =L18 -> 71396 | N18: =M18 -> 71396 | Q18: =SUM(I18:P18) -> 285584
A19: 0.42 | B19: 1558960 | C19: ЛУКОЙЛ ПОЛИФЛЕКС ЕР 0-160 | D19: кг | E19: 19260 | F19: 107 | G19: 180 | L19: =E19/4 -> 4815 | M19: =L19 -> 4815 | N19: =M19 -> 4815 | O19: =N19 -> 4815 | Q19: =SUM(I19:P19) -> 19260
A20: 0.43 | B20: 1558966 | C20: ЛУКОЙЛ ПОЛИФЛЕКС ЕР 1-160 | D20: кг | E20: 44820 | F20: 249 | G20: 180 | L20: =E20/4 -> 11205 | M20: =L20 -> 11205 | N20: =M20 -> 11205 | O20: =N20 -> 11205 | Q20: =SUM(I20:P20) -> 44820
A21: 0.44 | B21: 1682082 | C21: ЛУКОЙЛ КАРБОФЛЕКС OG 0-4000 HD | D21: кг | E21: 10620 | F21: 59 | G21: 180 | L21: =E21/4 -> 2655 | M21: =L21 -> 2655 | N21: =M21 -> 2655 | O21: =N21 -> 2655 | Q21: =SUM(I21:P21) -> 10620
A22: 0.46 | B22: 1559874 | C22: ЛУКОЙЛ ПОЛИФЛЕКС ЕР 2-160 HD | D22: кг | E22: 900 | F22: 5 | G22: 180 | L22: =E22/4 -> 225 | M22: =L22 -> 225 | N22: =M22 -> 225 | O22: =N22 -> 225 | Q22: =SUM(I22:P22) -> 900
A23: 0.48 | B23: 1682082 | C23: ЛУКОЙЛ КАРБОФЛЕКС OG 0-4000 HD | D23: кг | E23: 2160 | F23: 12 | G23: 180 | L23: =E23/4 -> 540 | M23: =L23 -> 540 | N23: =M23 -> 540 | O23: =N23 -> 540 | Q23: =SUM(I23:P23) -> 2160
A24: 0.49 | B24: 1683355 | C24: ЛУКОЙЛ КАРБОФЛЕКС OG 000-1500 HD | D24: кг | E24: 10080 | F24: 56 | G24: 180 | L24: =E24/4 -> 2520 | M24: =L24 -> 2520 | N24: =M24 -> 2520 | O24: =N24 -> 2520 | Q24: =SUM(I24:P24) -> 10080
A25: 0.50 | B25: 1683355 | C25: ЛУКОЙЛ КАРБОФЛЕКС OG 000-1500 HD | D25: кг | E25: 10080 | F25: 56 | G25: 180 | L25: =E25/4 -> 2520 | M25: =L25 -> 2520 | N25: =M25 -> 2520 | O25: =N25 -> 2520 | Q25: =SUM(I25:P25) -> 10080
A26: 0.51 | B26: 1615722 | C26: ЛУКОЙЛ ПОЛИФЛЕКС ЕР 1-160 HD | D26: кг | E26: 12780 | F26: 71 | G26: 180 | L26: =E26/4 -> 3195 | M26: =L26 -> 3195 | N26: =M26 -> 3195 | O26: =N26 -> 3195 | Q26: =SUM(I26:P26) -> 12780
A27: 0.52 | B27: 1615401 | C27: ЛУКОЙЛ ПОЛИФЛЕКС ЕР 1-160 HD | D27: кг | E27: 4224 | F27: 10560 | G27: 0.4 | L27: =E27 -> 4224 | Q27: =SUM(I27:P27) -> 4224
A28: 0.53 | B28: 1755295 | C28: ЛУКОЙЛ СИНТОФЛЕКС АРКТИК 1-100 HD - всесезонно/all season | D28: кг | E28: 29520 | F28: 164 | G28: 180 | L28: =E28/4 -> 7380 | M28: =L28 -> 7380 | N28: =M28 -> 7380 | O28: =N28 -> 7380 | Q28: =SUM(I28:P28) -> 29520
A29: 0.54 | B29: 1748233 | C29: ЛУКОЙЛ СИНТОФЛЕКС АРКТИК 1-100 HD - всесезонно/all season | D29: кг | E29: 10062 | F29: 559 | G29: 18 | L29: =E29 -> 10062 | Q29: =SUM(I29:P29) -> 10062
A30: 0.55 | B30: 14220301 | C30: LEMARC FFD / LEMARC FFD | D30: л | E30: 100 | F30: 100 | G30: 1 | O30: =E30 -> 100 | Q30: =SUM(I30:P30) -> 100
A31: 0.56 | B31: 14240401 | C31: LEMARC WINDGUARD 50 / LEMARC WINDGUARD 50 | D31: л | E31: 1000 | F31: 500 | G31: 2 | O31: =E31 -> 1000 | Q31: =SUM(I31:P31) -> 1000
A32: 0.57 | B32: 10050303 | C32: LEMARC DOT4 Low Temp / LEMARC DOT4 Low Temp | D32: л | E32: 1489 | F32: 1489 | G32: 1 | O32: =E32 -> 1489 | Q32: =SUM(I32:P32) -> 1489
C33: контейнер 20ф | D33: шт | E33: 106 | F33: 106 | G33: 1 | J33: 8 | K33: 14 | L33: 23 | M33: 20 | N33: 22 | O33: 19 | Q33: =SUM(J33:O33) -> 106
E34: =SUM(E4:E33) -> 1608373.7 | I34: =SUM(I4:I32) -> 0 | J34: =SUM(J4:J32) -> 123824 | K34: =SUM(K4:K32) -> 224201.33 | L34: =SUM(L4:L32) -> 349800.05 | M34: =SUM(M4:M32) -> 300844.33 | N34: =SUM(N4:N32) -> 339202.5 | O34: =SUM(O4:O32) -> 270395.5 | P34: =SUM(P4:P32) -> 0 | Q34: =SUM(Q4:Q32) -> 1608267.7
