Workbook

Sheet Read me
A1: Baimskaya — lubrication reference collection
A2: Карта сбора данных по смазочным материалам
A4: Fill in the YELLOW cells only
A5: Grey columns come from the app's own asset register. GREEN rows are already sourced —
A6: leave them alone unless you think they are wrong.
A8: Four rules that decide whether the data is usable
A9: 1. Capacity is the REFILL quantity — what goes in at a service, with the filter changed.
A10: Not the dry fill, not the sump volume. They differ by up to 20%, and the wrong one
A11: over-fills a final drive and blows the seal.
A12: 2. Copy the specification VERBATIM: "API CK-4 / Komatsu EO-DH", not "engine oil".
A13: The exact string is what gets matched against what a product claims.
A14: 3. A figure with no document and page shows as unsourced on the dashboard. That is
... A27: Progress — live, from the Compartments sheet
A28: Rows in the workbook | C28: =COUNTA(Compartments!D2:D400)
A29: Complete (four facts + a source) | C29: =COUNTIF(Compartments!R2:R400,"complete")
A30: Incomplete | C30: =COUNTIF(Compartments!R2:R400,"incomplete")
A31: Filled in but unsourced | C31: =COUNTIF(Compartments!R2:R400,"no source")
A32: Marked not fitted | C32: =COUNTIF(Compartments!R2:R400,"not fitted")
A33: Not started | C33: =COUNTIF(Compartments!R2:R400,"not started")
A34: Units covered by complete rows | C34: =SUMPRODUCT((Compartments!R2:R400="complete")*Compartments!C2:C400)
A36: These are live formulas. They fill in when you open this in Excel or Google Sheets — a blank there is not a fault.

Sheet Compartments
A1: Class | B1: Model | C1: Units | D1: Code | E1: Compartment (EN) | F1: Compartment (RU) | G1: Fitted? | H1: Refill L | I1: OEM specification (verbatim) | J1: Interval h | K1: Grade — winter (≤ −20 °C) | L1: Grade — summer (> −20 °C) | M1: Manual document | N1: Page | O1: Checked by | P1: Date | Q1: Notes | R1: Status
A2: AT | B2: KOMATSU | C2: 27 | D2: ENG | E2: Engine | F2: Двигатель | G2: Y | H2: 38 | I2: API CK-4 / Komatsu EO-DH | J2: 500 | K2: 5W-40 synth | L2: 15W-40 | Q2: Register says KOMATSU; identified as KOMATSU HM400 by R. Marrero | R2: =IF(UPPER(G2)="N","not fitted",IF(AND(H2="",I2="",J2=""),"not started",IF(OR(H2="",I2="",J2=""),"incomplete",IF(OR(M2="",N2=""),"no source","complete"))))
A3: AT | B3: KOMATSU | C3: 27 | D3: TRN | E3: Transmission | F3: Трансмиссия | G3: Y | H3: 60 | I3: KES 07.868.1 (TO-4 class) | J3: 2000 | K3: SAE 10W | L3: SAE 30 | M3: Komatsu SEN06084-01 p.4-12 | N3: see doc | O3: R. Marrero | P3: 2026-08-14 | Q3: Register says KOMATSU; identified as KOMATSU HM400 by R. Marrero | R3: =IF(UPPER(G3)="N","not fitted",IF(AND(H3="",I3="",J3=""),"not started",IF(OR(H3="",I3="",J3=""),"incomplete",IF(OR(M3="",N3=""),"no source","complete"))))
A4: AT | B4: KOMATSU | C4: 27 | D4: HYD | E4: Hydraulic | F4: Гидравлика | G4: Y | H4: 150 | I4: KES 07.859 / ISO VG | J4: 4000 | L4: ISO VG 32 | Q4: Register says KOMATSU; identified as KOMATSU HM400 by R. Marrero | R4: =IF(UPPER(G4)="N","not fitted",IF(AND(H4="",I4="",J4=""),"not started",IF(OR(H4="",I4="",J4=""),"incomplete",IF(OR(M4="",N4=""),"no source","complete"))))
A5: AT | B5: KOMATSU | C5: 27 | D5: FDL | E5: Final drive | F5: Бортовой редуктор | G5: Y | H5: 22 | I5: API GL-5 / KES 07.869 | J5: 2000 | K5: 75W-90 synth | L5: 80W-90 | Q5: Register says KOMATSU; identified as KOMATSU HM400 by R. Marrero | R5: =IF(UPPER(G5)="N","not fitted",IF(AND(H5="",I5="",J5=""),"not started",IF(OR(H5="",I5="",J5=""),"incomplete",IF(OR(M5="",N5=""),"no source","complete"))))
A6: AT | B6: KOMATSU | C6: 27 | D6: DIFF | E6: Differential | F6: Дифференциал | Q6: Register says KOMATSU; identified as KOMATSU HM400 by R. Marrero | R6: =IF(UPPER(G6)="N","not fitted",IF(AND(H6="",I6="",J6=""),"not started",IF(OR(H6="",I6="",J6=""),"incomplete",IF(OR(M6="",N6=""),"no source","complete"))))
A7: AT | B7: KOMATSU | C7: 27 | D7: TCASE | E7: Transfer case | F7: Раздаточная коробка | Q7: Register says KOMATSU; identified as KOMATSU HM400 by R. Marrero | R7: =IF(UPPER(G7)="N","not fitted",IF(AND(H7="",I7="",J7=""),"not started",IF(OR(H7="",I7="",J7=""),"incomplete",IF(OR(M7="",N7=""),"no source","complete"))))
A8: AT | B8: KOMATSU HM400 | C8: 1 | D8: ENG | E8: Engine | F8: Двигатель | G8: Y | H8: 38 | I8: API CK-4 / Komatsu EO-DH | J8: 500 | K8: 5W-40 synth | L8: 15W-40 | R8: =IF(UPPER(G8)="N","not fitted",IF(AND(H8="",I8="",J8=""),"not started",IF(OR(H8="",I8="",J8=""),"incomplete",IF(OR(M8="",N8=""),"no source","complete"))))
A9: AT | B9: KOMATSU HM400 | C9: 1 | D9: TRN | E9: Transmission | F9: Трансмиссия | G9: Y | H9: 60 | I9: KES 07.868.1 (TO-4 class) | J9: 2000 | K9: SAE 10W | L9: SAE 30 | M9: Komatsu SEN06084-01 p.4-12 | N9: see doc | O9: R. Marrero | P9: 2026-08-14 | R9: =IF(UPPER(G9)="N","not fitted",IF(AND(H9="",I9="",J9=""),"not started",IF(OR(H9="",I9="",J9=""),"incomplete",IF(OR(M9="",N9=""),"no source","complete"))))
A10: AT | B10: KOMATSU HM400 | C10: 1 | D10: HYD | E10: Hydraulic | F10: Гидравлика | G10: Y | H10: 150 | I10: KES 07.859 / ISO VG | J10: 4000 | L10: ISO VG 32 | R10: =IF(UPPER(G10)="N","not fitted",IF(AND(H10="",I10="",J10=""),"not started",IF(OR(H10="",I10="",J10=""),"incomplete",IF(OR(M10="",N10=""),"no source","complete"))))
A11: AT | B11: KOMATSU HM400 | C11: 1 | D11: FDL | E11: Final drive | F11: Бортовой редуктор | G11: Y | H11: 22 | I11: API GL-5 / KES 07.869 | J11: 2000 | K11: 75W-90 synth | L11: 80W-90 | R11: =IF(UPPER(G11)="N","not fitted",IF(AND(H11="",I11="",J11=""),"not started",IF(OR(H11="",I11="",J11=""),"incomplete",IF(OR(M11="",N11=""),"no source","complete"))))
A12: AT | B12: KOMATSU HM400 | C12: 1 | D12: DIFF | E12: Differential | F12: Дифференциал | R12: =IF(UPPER(G12)="N","not fitted",IF(AND(H12="",I12="",J12=""),"not started",IF(OR(H12="",I12="",J12=""),"incomplete",IF(OR(M12="",N12=""),"no source","complete"))))
A13: AT | B13: KOMATSU HM400 | C13: 1 | D13: TCASE | E13: Transfer case | F13: Раздаточная коробка | R13: =IF(UPPER(G13)="N","not fitted",IF(AND(H13="",I13="",J13=""),"not started",IF(OR(H13="",I13="",J13=""),"incomplete",IF(OR(M13="",N13=""),"no source","complete"))))
A14: CRC | B14: NMS MT300MC | C14: 2 | D14: ENG | E14: Engine | F14: Двигатель | R14: =IF(UPPER(G14)="N","not fitted",IF(AND(H14="",I14="",J14=""),"not started",IF(OR(H14="",I14="",J14=""),"incomplete",IF(OR(M14="",N14=""),"no source","complete"))))
A15: CRC | B15: NMS MT300MC | C15: 2 | D15: HYD | E15: Hydraulic | F15: Гидравлика | R15: =IF(UPPER(G15)="N","not fitted",IF(AND(H15="",I15="",J15=""),"not started",IF(OR(H15="",I15="",J15=""),"incomplete",IF(OR(M15="",N15=""),"no source","complete"))))
A16: CRC | B16: NMS MT300MC | C16: 2 | D16: MSH | E16: Main shaft / cone oil | F16: Главный вал / масло конуса | R16: =IF(UPPER(G16)="N","not fitted",IF(AND(H16="",I16="",J16=""),"not started",IF(OR(H16="",I16="",J16=""),"incomplete",IF(OR(M16="",N16=""),"no source","complete"))))
A17: CRC | B17: NMS MT300MC | C17: 2 | D17: DRV | E17: Drive gearbox | F17: Редуктор привода | R17: =IF(UPPER(G17)="N","not fitted",IF(AND(H17="",I17="",J17=""),"not started",IF(OR(H17="",I17="",J17=""),"incomplete",IF(OR(M17="",N17=""),"no source","complete"))))
A18: CRC | B18: NMS MT300MC | C18: 2 | D18: LUB | E18: Lube tank | F18: Бак смазки | R18: =IF(UPPER(G18)="N","not fitted",IF(AND(H18="",I18="",J18=""),"not started",IF(OR(H18="",I18="",J18=""),"incomplete",IF(OR(M18="",N18=""),"no source","complete"))))
A19: CRC | B19: MCCLOSKEY C38 | C19: 1 | D19: ENG | E19: Engine | F19: Двигатель | R19: =IF(UPPER(G19)="N","not fitted",IF(AND(H19="",I19="",J19=""),"not started",IF(OR(H19="",I19="",J19=""),"incomplete",IF(OR(M19="",N19=""),"no source","complete"))))
A20: CRC | B20: MCCLOSKEY C38 | C20: 1 | D20: HYD | E20: Hydraulic | F20: Гидравлика | R20: =IF(UPPER(G20)="N","not fitted",IF(AND(H20="",I20="",J20=""),"not started",IF(OR(H20="",I20="",J20=""),"incomplete",IF(OR(M20="",N20=""),"no source","complete"))))
A21: CRC | B21: MCCLOSKEY C38 | C21: 1 | D21: MSH | E21: Main shaft / cone oil | F21: Главный вал / масло конуса | R21: =IF(UPPER(G21)="N","not fitted",IF(AND(H21="",I21="",J21=""),"not started",IF(OR(H21="",I21="",J21=""),"incomplete",IF(OR(M21="",N21=""),"no source","complete"))))
A22: CRC | B22: MCCLOSKEY C38 | C22: 1 | D22: DRV | E22: Drive gearbox | F22: Редуктор привода | R22: =IF(UPPER(G22)="N","not fitted",IF(AND(H22="",I22="",J22=""),"not started",IF(OR(H22="",I22="",J22=""),"incomplete",IF(OR(M22="",N22=""),"no source","complete"))))
A23: CRC | B23: MCCLOSKEY C38 | C23: 1 | D23: LUB | E23: Lube tank | F23: Бак смазки | R23: =IF(UPPER(G23)="N","not fitted",IF(AND(H23="",I23="",J23=""),"not started",IF(OR(H23="",I23="",J23=""),"incomplete",IF(OR(M23="",N23=""),"no source","complete"))))
... A43: CRJ | B43: MCCLOSKEY J50V2 | C43: 1 | D43: LUB | E43: Lube tank | F43: Бак смазки | R43: =IF(UPPER(G43)="N","not fitted",IF(AND(H43="",I43="",J43=""),"not started",IF(OR(H43="",I43="",J43=""),"incomplete",IF(OR(M43="",N43=""),"no source","complete"))))
A44: DOZ | B44: KOMATSU D375A.6 | C44: 5 | D44: ENG | E44: Engine | F44: Двигатель | G44: Y | H44: 60 | I44: API CK-4 / Komatsu EO-DH | J44: 500 | K44: 5W-40 synth | L44: 15W-40 | R44: =IF(UPPER(G44)="N","not fitted",IF(AND(H44="",I44="",J44=""),"not started",IF(OR(H44="",I44="",J44=""),"incomplete",IF(OR(M44="",N44=""),"no source","complete"))))
A45: DOZ | B45: KOMATSU D375A.6 | C45: 5 | D45: TRN | E45: Powertrain / torque converter | F45: Трансмиссия / гидротрансформатор | G45: Y | H45: 110 | I45: KES 07.868.1 (TO-4 class) | J45: 2000 | K45: SAE 10W | L45: SAE 30 | R45: =IF(UPPER(G45)="N","not fitted",IF(AND(H45="",I45="",J45=""),"not started",IF(OR(H45="",I45="",J45=""),"incomplete",IF(OR(M45="",N45=""),"no source","complete"))))
A46: DOZ | B46: KOMATSU D375A.6 | C46: 5 | D46: HYD | E46: Hydraulic | F46: Гидравлика | R46: =IF(UPPER(G46)="N","not fitted",IF(AND(H46="",I46="",J46=""),"not started",IF(OR(H46="",I46="",J46=""),"incomplete",IF(OR(M46="",N46=""),"no source","complete"))))
A47: DOZ | B47: KOMATSU D375A.6 | C47: 5 | D47: FDL | E47: Final drive | F47: Бортовой редуктор | G47: Y | H47: 38 | I47: KES 07.868.1 | J47: 2000 | K47: SAE 10W | L47: SAE 30 | R47: =IF(UPPER(G47)="N","not fitted",IF(AND(H47="",I47="",J47=""),"not started",IF(OR(H47="",I47="",J47=""),"incomplete",IF(OR(M47="",N47=""),"no source","complete"))))
A48: DOZ | B48: KOMATSU D375A.6 | C48: 5 | D48: PIV | E48: Pivot shaft | F48: Ось качания | R48: =IF(UPPER(G48)="N","not fitted",IF(AND(H48="",I48="",J48=""),"not started",IF(OR(H48="",I48="",J48=""),"incomplete",IF(OR(M48="",N48=""),"no source","complete"))))
A49: DOZ | B49: SHANTUI SD32 | C49: 5 | D49: ENG | E49: Engine | F49: Двигатель | G49: Y | H49: 32 | I49: API CI-4 | J49: 500 | K49: 5W-40 synth | L49: 15W-40 | R49: =IF(UPPER(G49)="N","not fitted",IF(AND(H49="",I49="",J49=""),"not started",IF(OR(H49="",I49="",J49=""),"incomplete",IF(OR(M49="",N49=""),"no source","complete"))))
A50: DOZ | B50: SHANTUI SD32 | C50: 5 | D50: TRN | E50: Powertrain / torque converter | F50: Трансмиссия / гидротрансформатор | G50: Y | H50: 85 | I50: SAE 30 powertrain (TO-4 class) | J50: 2000 | K50: SAE 10W | L50: SAE 30 | R50: =IF(UPPER(G50)="N","not fitted",IF(AND(H50="",I50="",J50=""),"not started",IF(OR(H50="",I50="",J50=""),"incomplete",IF(OR(M50="",N50=""),"no source","complete"))))
A51: DOZ | B51: SHANTUI SD32 | C51: 5 | D51: HYD | E51: Hydraulic | F51: Гидравлика | R51: =IF(UPPER(G51)="N","not fitted",IF(AND(H51="",I51="",J51=""),"not started",IF(OR(H51="",I51="",J51=""),"incomplete",IF(OR(M51="",N51=""),"no source","complete"))))
A52: DOZ | B52: SHANTUI SD32 | C52: 5 | D52: FDL | E52: Final drive | F52: Бортовой редуктор | R52: =IF(UPPER(G52)="N","not fitted",IF(AND(H52="",I52="",J52=""),"not started",IF(OR(H52="",I52="",J52=""),"incomplete",IF(OR(M52="",N52=""),"no source","complete"))))
A53: DOZ | B53: SHANTUI SD32 | C53: 5 | D53: PIV | E53: Pivot shaft | F53: Ось качания | R53: =IF(UPPER(G53)="N","not fitted",IF(AND(H53="",I53="",J53=""),"not started",IF(OR(H53="",I53="",J53=""),"incomplete",IF(OR(M53="",N53=""),"no source","complete"))))
A54: DOZ | B54: SHANTUI SD60-C5 | C54: 3 | D54: ENG | E54: Engine | F54: Двигатель | R54: =IF(UPPER(G54)="N","not fitted",IF(AND(H54="",I54="",J54=""),"not started",IF(OR(H54="",I54="",J54=""),"incomplete",IF(OR(M54="",N54=""),"no source","complete"))))
A55: DOZ | B55: SHANTUI SD60-C5 | C55: 3 | D55: TRN | E55: Powertrain / torque converter | F55: Трансмиссия / гидротрансформатор | R55: =IF(UPPER(G55)="N","not fitted",IF(AND(H55="",I55="",J55=""),"not started",IF(OR(H55="",I55="",J55=""),"incomplete",IF(OR(M55="",N55=""),"no source","complete"))))
A56: DOZ | B56: SHANTUI SD60-C5 | C56: 3 | D56: HYD | E56: Hydraulic | F56: Гидравлика | R56: =IF(UPPER(G56)="N","not fitted",IF(AND(H56="",I56="",J56=""),"not started",IF(OR(H56="",I56="",J56=""),"incomplete",IF(OR(M56="",N56=""),"no source","complete"))))
A57: DOZ | B57: SHANTUI SD60-C5 | C57: 3 | D57: FDL | E57: Final drive | F57: Бортовой редуктор | R57: =IF(UPPER(G57)="N","not fitted",IF(AND(H57="",I57="",J57=""),"not started",IF(OR(H57="",I57="",J57=""),"incomplete",IF(OR(M57="",N57=""),"no source","complete"))))
A58: DOZ | B58: SHANTUI SD60-C5 | C58: 3 | D58: PIV | E58: Pivot shaft | F58: Ось качания | R58: =IF(UPPER(G58)="N","not fitted",IF(AND(H58="",I58="",J58=""),"not started",IF(OR(H58="",I58="",J58=""),"incomplete",IF(OR(M58="",N58=""),"no source","complete"))))
A59: DOZ | B59: CATERPILLAR D9R | C59: 2 | D59: ENG | E59: Engine | F59: Двигатель | G59: Y | H59: 38 | I59: Cat ECF-3 / API CK-4 | J59: 500 | K59: 0W-40 arctic synth | L59: 15W-40 | R59: =IF(UPPER(G59)="N","not fitted",IF(AND(H59="",I59="",J59=""),"not started",IF(OR(H59="",I59="",J59=""),"incomplete",IF(OR(M59="",N59=""),"no source","complete"))))
...

Sheet Products in use
A1: Product name (as printed on the label) | B1: Grade | C1: Specifications it claims (verbatim from the PDS) | D1: Lowest ambient it is rated to (°C) | E1: Where it is held | F1: Tank / drum ID | G1: Approx. stock (L) | H1: Photo of label taken? | I1: Notes
A2: Mobil Delvac 1 5W-40 | B2: 5W-40 synth | C2: API CK-4, Cat ECF-3, Komatsu EO-DH | D2: -40
A3: Cat Arctic DEO SYN 0W-40 | B3: 0W-40 arctic synth | C3: Cat ECF-3, API CK-4 | D3: -45
A4: Lukoil Avangard Ultra 15W-40 | B4: 15W-40 | C4: API CI-4 | D4: -15
A5: Shell Spirax S4 TXM | B5: SAE 10W | C5: CAT TO-4, KES 07.868.1, Allison C-4 | D5: -40
A6: Komatsu Powertrain TO-10 | B6: SAE 10W | C6: KES 07.868.1, CAT TO-4 | D6: -40
A7: Cat TDTO-TMS (arctic) | B7: TDTO-TMS (arctic) | C7: CAT TO-4, TO-4M | D7: -45
A8: Generic TO-4 SAE 30 | B8: SAE 30 | C8: CAT TO-4 | D8: -10
A9: Cat HYDO Advanced 10 | B9: HYDO Adv 10 | C9: Cat HYDO Advanced, ISO VG 32 | D9: -30
A10: HVLP 32 arctic | B10: ISO VG 32 | C10: DIN 51524-3, ISO VG 32 | D10: -35
A11: HVLP 22 arctic synth | B11: ISO VG 22 | C11: DIN 51524-3, ISO VG 22, ISO VG 32, Hitachi Super EX | D11: -45
A12: HLP 46 | B12: ISO VG 46 | C12: DIN 51524-2, ISO VG 46 | D12: -10
A13: Mobilube SHC 75W-90 | B13: 75W-90 synth | C13: API GL-5 | D13: -45
... A15: UTTO universal tractor fluid | B15: SAE 10W | C15: Wet brake WB-101 | D15: -25
A48: Blue rows are what the app currently believes is available. Correct them, and add anything on site that is missing — including drums you suspect are wrong.

Sheet Register gaps
A1: Units the register records by make only
A2: A capacity cannot be attached to "KOMATSU". Where somebody has identified the machine, the app uses those figures today — but the register is still wrong and these stay listed until the model is recorded in 1C.
A4: Class | B4: Recorded as | C4: Units | D4: Identified as | E4: By | F4: Actual model (confirm / fill in) | G4: Fixed in 1C?
A5: AT | B5: KOMATSU | C5: 27 | D5: KOMATSU HM400 | E5: R. Marrero
A6: LDR | B6: ELAZ | C6: 2
A7: LDR | B7: HYUNDAI | C7: 3
A8: LDR | B8: KOMATSU | C8: 5
B9: Total | C9: =SUM(C5:C8)

Sheet Site
A1: Site constants
A2: Every cold-weather verdict is computed against these. Getting the design minimum wrong changes which products qualify.
A4: Item | B4: Value | C4: Note
A5: Design minimum ambient (°C) | B5: -40 | C5: The temperature the oil must still work at — usually not the record low.
A6: Record winter low (°C) | B6: -45 | C6: Reference only.
A7: Summer high (°C) | B7: 28
A8: Operating hours per machine per year | B8: 5000 | C8: Drives how fast an audit goes stale.
A9: Lube audit crews available | B9: 2
A10: Compartments one crew can audit per day | B10: 6
A11: Oil analysis laboratory | C11: Name, and whether they can export results as CSV.
A12: Who signs off the site standard | C12: One name. A standard anyone can change is not a standard.
